<?xml version="1.0" ?>
<!--
  person_actor.sdf  –  Keyboard-controlled person model
  ─────────────────────────────────────────────────────────────────────────────
  This is NOT a Gazebo scripted actor.
  It is a regular robot model (capsule body) driven by the DiffDrive plugin,
  so it can receive /person/cmd_vel from ROS 2 and move freely.

  The teleop_person_node.py reads the keyboard and publishes:
    /person/cmd_vel   → moves this model (WASD keys)
    /remote/button    → remote button signal (keys 1, 2, 3)

  Body design:
    - Tall capsule = human torso silhouette (LiDAR sees it clearly)
    - Cyan glowing sphere on top = UWB remote (signal source)
    - Two small wheels (hidden under base) for DiffDrive locomotion
    - Collision radius 0.25m = realistic human width

  Spawned via launch file at position: x=1.5, y=0, z=0
-->
<sdf version="1.10">
  <model name="person">

    <pose>1.5 0.0 0.0 0 0 0</pose>

    <!-- ── BASE LINK (main body – tall capsule shape) ─────────────────── -->
    <link name="base_link">
      <pose>0 0 0.5 0 0 0</pose>

      <inertial>
        <pose>0 0 -0.3 0 0 0</pose>
        <mass>70.0</mass>
        <inertia>
          <ixx>5.0</ixx><iyy>5.0</iyy><izz>1.0</izz>
          <ixy>0</ixy><ixz>0</ixz><iyz>0</iyz>
        </inertia>
      </inertial>

      <!-- Main body cylinder (torso) -->
      <collision name="body_col">
        <geometry>
          <cylinder><radius>0.25</radius><length>0.8</length></cylinder>
        </geometry>
      </collision>

      <!-- Body visual – warm skin tone -->
      <visual name="body_vis">
        <geometry>
          <cylinder><radius>0.25</radius><length>0.8</length></cylinder>
        </geometry>
        <material>
          <ambient>0.88 0.70 0.50 1</ambient>
          <diffuse>0.88 0.70 0.50 1</diffuse>
          <specular>0.2 0.2 0.2 1</specular>
        </material>
      </visual>

      <!-- Head sphere -->
      <visual name="head_vis">
        <pose>0 0 0.55 0 0 0</pose>
        <geometry>
          <sphere><radius>0.18</radius></sphere>
        </geometry>
        <material>
          <ambient>0.88 0.70 0.50 1</ambient>
          <diffuse>0.88 0.70 0.50 1</diffuse>
        </material>
      </visual>

      <!-- UWB Remote device – glowing cyan box held at chest height -->
      <visual name="remote_vis">
        <pose>0.22 0 0.30 0 0 0</pose>
        <geometry>
          <box><size>0.08 0.04 0.12</size></box>
        </geometry>
        <material>
          <ambient>0.0  0.9  1.0  1.0</ambient>
          <diffuse>0.0  0.9  1.0  1.0</diffuse>
          <emissive>0.0 0.8  1.0  1.0</emissive>
          <specular>0.5 0.5  0.5  1.0</specular>
        </material>
      </visual>

      <!-- UWB signal glow – pulsing sphere around the remote -->
      <visual name="uwb_glow">
        <pose>0.22 0 0.30 0 0 0</pose>
        <geometry>
          <sphere><radius>0.18</radius></sphere>
        </geometry>
        <material>
          <ambient>0.0  1.0  1.0  0.3</ambient>
          <diffuse>0.0  1.0  1.0  0.3</diffuse>
          <emissive>0.0 0.9  1.0  1.0</emissive>
        </material>
        <transparency>0.70</transparency>
      </visual>

      <!-- Outer UWB ring (larger, more transparent) -->
      <visual name="uwb_ring">
        <pose>0.22 0 0.30 0 0 0</pose>
        <geometry>
          <sphere><radius>0.32</radius></sphere>
        </geometry>
        <material>
          <ambient>0.0  0.85 1.0  0.12</ambient>
          <diffuse>0.0  0.85 1.0  0.12</diffuse>
          <emissive>0.0 0.75 1.0  1.0</emissive>
        </material>
        <transparency>0.88</transparency>
      </visual>

    </link>

    <!-- ── WHEELS (small, tucked under body – just for DiffDrive physics) -->
    <link name="left_wheel">
      <pose>0 0.20 0.1 1.5708 0 0</pose>
      <inertial>
        <mass>1.0</mass>
        <inertia><ixx>0.01</ixx><iyy>0.01</iyy><izz>0.01</izz><ixy>0</ixy><ixz>0</ixz><iyz>0</iyz></inertia>
      </inertial>
      <collision name="col">
        <geometry><cylinder><radius>0.10</radius><length>0.04</length></cylinder></geometry>
      </collision>
      <!-- Wheels hidden (same colour as ground) so person looks natural -->
      <visual name="vis">
        <geometry><cylinder><radius>0.10</radius><length>0.04</length></cylinder></geometry>
        <material><ambient>0.82 0.82 0.78 1</ambient><diffuse>0.82 0.82 0.78 1</diffuse></material>
      </visual>
      <surface>
        <friction>
          <ode>
            <mu>1.0</mu>
            <mu2>1.0</mu2>
          </ode>
        </friction>
      </surface>
    </link>

    <link name="right_wheel">
      <pose>0 -0.20 0.1 1.5708 0 0</pose>
      <inertial>
        <mass>1.0</mass>
        <inertia><ixx>0.01</ixx><iyy>0.01</iyy><izz>0.01</izz><ixy>0</ixy><ixz>0</ixz><iyz>0</iyz></inertia>
      </inertial>
      <collision name="col">
        <geometry><cylinder><radius>0.10</radius><length>0.04</length></cylinder></geometry>
      </collision>
      <visual name="vis">
        <geometry><cylinder><radius>0.10</radius><length>0.04</length></cylinder></geometry>
        <material><ambient>0.82 0.82 0.78 1</ambient><diffuse>0.82 0.82 0.78 1</diffuse></material>
      </visual>
      <surface>
        <friction>
          <ode>
            <mu>1.0</mu>
            <mu2>1.0</mu2>
          </ode>
        </friction>
      </surface>
    </link>

    <!-- Caster wheel to keep the actor balance -->
    <link name="caster_wheel">
      <pose>-0.20 0 0.10 0 0 0</pose>  

      <inertial>
        <mass>1.0</mass>
        <inertia>
          <ixx>0.01</ixx><iyy>0.01</iyy><izz>0.01</izz>
          <ixy>0</ixy><ixz>0</ixz><iyz>0</iyz>
        </inertia>
      </inertial>

      <collision name="caster_col">
        <geometry>
          <sphere><radius>0.10</radius></sphere> 
        </geometry>

        <surface>
          <friction>
            <ode>
              <mu>0.02</mu>
              <mu2>0.02</mu2>
            </ode>
          </friction>
        </surface>
      </collision>

      <visual name="caster_vis">
        <geometry>
          <sphere><radius>0.10</radius></sphere>
        </geometry>
        <material>
          <ambient>0.1 0.1 0.1 1</ambient>
          <diffuse>0.1 0.1 0.1 1</diffuse>
        </material>
      </visual>
    </link>

    <link name="front_caster">
      <pose>0.20 0 0.10 0 0 0</pose>  

      <inertial>
        <mass>1.0</mass>
        <inertia>
          <ixx>0.01</ixx><iyy>0.01</iyy><izz>0.01</izz>
          <ixy>0</ixy><ixz>0</ixz><iyz>0</iyz>
        </inertia>
      </inertial>

      <collision name="caster_col">
        <geometry>
          <sphere><radius>0.10</radius></sphere>
        </geometry>

        <surface>
          <friction>
            <ode>
              <mu>0.02</mu>
              <mu2>0.02</mu2>
            </ode>
          </friction>
        </surface>
      </collision>

      <visual name="caster_vis">
        <geometry>
          <sphere><radius>0.10</radius></sphere>
        </geometry>
        <material>
          <ambient>0.1 0.1 0.1 1</ambient>
          <diffuse>0.1 0.1 0.1 1</diffuse>
        </material>
      </visual>
    </link>


    <!-- ── JOINTS ─────────────────────────────────────────────────────── -->
    <joint name="left_wheel_joint" type="revolute">
      <parent>base_link</parent>
      <child>left_wheel</child>
      <axis>
        <xyz>0 0 1</xyz>
        <limit><lower>-1e16</lower><upper>1e16</upper></limit>
      </axis>
    </joint>

    <joint name="right_wheel_joint" type="revolute">
      <parent>base_link</parent>
      <child>right_wheel</child>
      <axis>
        <xyz>0 0 1</xyz>
        <limit><lower>-1e16</lower><upper>1e16</upper></limit>
      </axis>
    </joint>

    <joint name="caster_joint" type="fixed">
      <parent>base_link</parent>
      <child>caster_wheel</child>
    </joint>

    <joint name="front_caster_joint" type="fixed">
      <parent>base_link</parent>
      <child>front_caster</child>
    </joint>


    <!-- ── DIFF DRIVE PLUGIN – receives /person/cmd_vel ──────────────── -->
    <plugin filename="gz-sim-diff-drive-system"
            name="gz::sim::systems::DiffDrive">
      <left_joint>left_wheel_joint</left_joint>
      <right_joint>right_wheel_joint</right_joint>
      <wheel_separation>0.50</wheel_separation>
      <wheel_radius>0.10</wheel_radius>
      <max_linear_velocity>1.5</max_linear_velocity>
      <max_angular_velocity>2.0</max_angular_velocity>
      <max_linear_acceleration>2.0</max_linear_acceleration>
      <odom_publish_frequency>20</odom_publish_frequency>
      <topic>person/cmd_vel</topic>
      <odom_topic>person/odom</odom_topic>
      <tf_topic>person/tf</tf_topic>
      <frame_id>person_odom</frame_id>
      <child_frame_id>person</child_frame_id>
    </plugin>

    <!-- Joint state publisher for person wheels -->
    <plugin filename="gz-sim-joint-state-publisher-system"
            name="gz::sim::systems::JointStatePublisher">
      <topic>person/joint_states</topic>
    </plugin>

  </model>
</sdf>
